[2024-09-13T16:05:14.158+0000] {taskinstance.py:1087} INFO - Dependencies all met for <TaskInstance: etl_pipeline_dag.load_task manual__2024-09-13T16:05:09.090013+00:00 [queued]>
[2024-09-13T16:05:14.169+0000] {taskinstance.py:1087} INFO - Dependencies all met for <TaskInstance: etl_pipeline_dag.load_task manual__2024-09-13T16:05:09.090013+00:00 [queued]>
[2024-09-13T16:05:14.179+0000] {taskinstance.py:1283} INFO - 
--------------------------------------------------------------------------------
[2024-09-13T16:05:14.180+0000] {taskinstance.py:1284} INFO - Starting attempt 1 of 1
[2024-09-13T16:05:14.180+0000] {taskinstance.py:1285} INFO - 
--------------------------------------------------------------------------------
[2024-09-13T16:05:14.198+0000] {taskinstance.py:1304} INFO - Executing <Task(PythonOperator): load_task> on 2024-09-13 16:05:09.090013+00:00
[2024-09-13T16:05:14.201+0000] {standard_task_runner.py:55} INFO - Started process 301 to run task
[2024-09-13T16:05:14.204+0000] {standard_task_runner.py:82} INFO - Running: ['***', 'tasks', 'run', 'etl_pipeline_dag', 'load_task', 'manual__2024-09-13T16:05:09.090013+00:00', '--job-id', '43', '--raw', '--subdir', 'DAGS_FOLDER/etl_pipeline.py', '--cfg-path', '/tmp/tmpmuyc5e84']
[2024-09-13T16:05:14.317+0000] {standard_task_runner.py:83} INFO - Job 43: Subtask load_task
[2024-09-13T16:05:14.329+0000] {logging_mixin.py:137} WARNING - /home/***/.local/lib/python3.7/site-packages/***/settings.py:249 DeprecationWarning: The sql_alchemy_conn option in [core] has been moved to the sql_alchemy_conn option in [database] - the old setting has been used, but please update your config.
[2024-09-13T16:05:14.369+0000] {task_command.py:389} INFO - Running <TaskInstance: etl_pipeline_dag.load_task manual__2024-09-13T16:05:09.090013+00:00 [running]> on host 2656b950921d
[2024-09-13T16:05:14.511+0000] {taskinstance.py:1513} INFO - Exporting the following env vars:
AIRFLOW_CTX_DAG_OWNER=***
AIRFLOW_CTX_DAG_ID=etl_pipeline_dag
AIRFLOW_CTX_TASK_ID=load_task
AIRFLOW_CTX_EXECUTION_DATE=2024-09-13T16:05:09.090013+00:00
AIRFLOW_CTX_TRY_NUMBER=1
AIRFLOW_CTX_DAG_RUN_ID=manual__2024-09-13T16:05:09.090013+00:00
[2024-09-13T16:05:14.542+0000] {logging_mixin.py:137} INFO - Failed to load data into PostgreSQL: 'record_date'
[2024-09-13T16:05:14.542+0000] {taskinstance.py:1772} ERROR - Task failed with exception
Traceback (most recent call last):
  File "/home/airflow/.local/lib/python3.7/site-packages/pandas/core/indexes/base.py", line 3361, in get_loc
    return self._engine.get_loc(casted_key)
  File "pandas/_libs/index.pyx", line 76, in pandas._libs.index.IndexEngine.get_loc
  File "pandas/_libs/index.pyx", line 108, in pandas._libs.index.IndexEngine.get_loc
  File "pandas/_libs/hashtable_class_helper.pxi", line 5198, in pandas._libs.hashtable.PyObjectHashTable.get_item
  File "pandas/_libs/hashtable_class_helper.pxi", line 5206, in pandas._libs.hashtable.PyObjectHashTable.get_item
KeyError: 'record_date'

The above exception was the direct cause of the following exception:

Traceback (most recent call last):
  File "/home/airflow/.local/lib/python3.7/site-packages/airflow/operators/python.py", line 175, in execute
    return_value = self.execute_callable()
  File "/home/airflow/.local/lib/python3.7/site-packages/airflow/operators/python.py", line 192, in execute_callable
    return self.python_callable(*self.op_args, **self.op_kwargs)
  File "/opt/airflow/tasks/loader.py", line 31, in loader
    row['record_date'], row['confirmed'], row['deaths'], row['recovered'], row['active'],
  File "/home/airflow/.local/lib/python3.7/site-packages/pandas/core/series.py", line 942, in __getitem__
    return self._get_value(key)
  File "/home/airflow/.local/lib/python3.7/site-packages/pandas/core/series.py", line 1051, in _get_value
    loc = self.index.get_loc(label)
  File "/home/airflow/.local/lib/python3.7/site-packages/pandas/core/indexes/base.py", line 3363, in get_loc
    raise KeyError(key) from err
KeyError: 'record_date'
[2024-09-13T16:05:14.552+0000] {taskinstance.py:1327} INFO - Marking task as FAILED. dag_id=etl_pipeline_dag, task_id=load_task, execution_date=20240913T160509, start_date=20240913T160514, end_date=20240913T160514
[2024-09-13T16:05:14.562+0000] {standard_task_runner.py:105} ERROR - Failed to execute job 43 for task load_task ('record_date'; 301)
[2024-09-13T16:05:14.585+0000] {local_task_job.py:159} INFO - Task exited with return code 1
[2024-09-13T16:05:14.692+0000] {taskinstance.py:2582} INFO - 0 downstream tasks scheduled from follow-on schedule check
