[2024-09-12T02:57:43.056+0000] {taskinstance.py:1087} INFO - Dependencies all met for <TaskInstance: etl_pipeline_dag.extract_task manual__2024-09-12T02:57:42.537829+00:00 [queued]>
[2024-09-12T02:57:43.065+0000] {taskinstance.py:1087} INFO - Dependencies all met for <TaskInstance: etl_pipeline_dag.extract_task manual__2024-09-12T02:57:42.537829+00:00 [queued]>
[2024-09-12T02:57:43.066+0000] {taskinstance.py:1283} INFO - 
--------------------------------------------------------------------------------
[2024-09-12T02:57:43.066+0000] {taskinstance.py:1284} INFO - Starting attempt 1 of 1
[2024-09-12T02:57:43.066+0000] {taskinstance.py:1285} INFO - 
--------------------------------------------------------------------------------
[2024-09-12T02:57:43.076+0000] {taskinstance.py:1304} INFO - Executing <Task(PythonOperator): extract_task> on 2024-09-12 02:57:42.537829+00:00
[2024-09-12T02:57:43.079+0000] {standard_task_runner.py:55} INFO - Started process 420 to run task
[2024-09-12T02:57:43.082+0000] {standard_task_runner.py:82} INFO - Running: ['***', 'tasks', 'run', 'etl_pipeline_dag', 'extract_task', 'manual__2024-09-12T02:57:42.537829+00:00', '--job-id', '24', '--raw', '--subdir', 'DAGS_FOLDER/etl_pipeline.py', '--cfg-path', '/tmp/tmpayify9f5']
[2024-09-12T02:57:43.192+0000] {standard_task_runner.py:83} INFO - Job 24: Subtask extract_task
[2024-09-12T02:57:43.202+0000] {logging_mixin.py:137} WARNING - /home/***/.local/lib/python3.7/site-packages/***/settings.py:249 DeprecationWarning: The sql_alchemy_conn option in [core] has been moved to the sql_alchemy_conn option in [database] - the old setting has been used, but please update your config.
[2024-09-12T02:57:43.243+0000] {task_command.py:389} INFO - Running <TaskInstance: etl_pipeline_dag.extract_task manual__2024-09-12T02:57:42.537829+00:00 [running]> on host 94e336337df0
[2024-09-12T02:57:43.304+0000] {taskinstance.py:1513} INFO - Exporting the following env vars:
AIRFLOW_CTX_DAG_OWNER=***
AIRFLOW_CTX_DAG_ID=etl_pipeline_dag
AIRFLOW_CTX_TASK_ID=extract_task
AIRFLOW_CTX_EXECUTION_DATE=2024-09-12T02:57:42.537829+00:00
AIRFLOW_CTX_TRY_NUMBER=1
AIRFLOW_CTX_DAG_RUN_ID=manual__2024-09-12T02:57:42.537829+00:00
[2024-09-12T02:57:43.387+0000] {logging_mixin.py:137} WARNING - /home/***/.local/lib/python3.7/site-packages/urllib3/connectionpool.py:1052 InsecureRequestWarning: Unverified HTTPS request is being made to host 'raw.githubusercontent.com'. Adding certificate verification is strongly advised. See: https://urllib3.readthedocs.io/en/1.26.x/advanced-usage.html#ssl-warnings
[2024-09-12T02:57:43.659+0000] {logging_mixin.py:137} INFO - Failed to extract data from https://raw.githubusercontent.com/CSSEGISandData/COVID-19/master/csse_covid_19_data/csse_covid_19_daily_reports/: 400 Client Error: Bad Request for url: https://raw.githubusercontent.com/CSSEGISandData/COVID-19/master/csse_covid_19_data/csse_covid_19_daily_reports/
[2024-09-12T02:57:43.661+0000] {taskinstance.py:1772} ERROR - Task failed with exception
Traceback (most recent call last):
  File "/home/airflow/.local/lib/python3.7/site-packages/airflow/operators/python.py", line 175, in execute
    return_value = self.execute_callable()
  File "/home/airflow/.local/lib/python3.7/site-packages/airflow/operators/python.py", line 192, in execute_callable
    return self.python_callable(*self.op_args, **self.op_kwargs)
  File "/opt/airflow/tasks/extractor.py", line 15, in extractor
    response.raise_for_status()
  File "/home/airflow/.local/lib/python3.7/site-packages/requests/models.py", line 1021, in raise_for_status
    raise HTTPError(http_error_msg, response=self)
requests.exceptions.HTTPError: 400 Client Error: Bad Request for url: https://raw.githubusercontent.com/CSSEGISandData/COVID-19/master/csse_covid_19_data/csse_covid_19_daily_reports/
[2024-09-12T02:57:43.680+0000] {taskinstance.py:1327} INFO - Marking task as FAILED. dag_id=etl_pipeline_dag, task_id=extract_task, execution_date=20240912T025742, start_date=20240912T025743, end_date=20240912T025743
[2024-09-12T02:57:43.693+0000] {standard_task_runner.py:105} ERROR - Failed to execute job 24 for task extract_task (400 Client Error: Bad Request for url: https://raw.githubusercontent.com/CSSEGISandData/COVID-19/master/csse_covid_19_data/csse_covid_19_daily_reports/; 420)
[2024-09-12T02:57:43.738+0000] {local_task_job.py:159} INFO - Task exited with return code 1
[2024-09-12T02:57:43.856+0000] {taskinstance.py:2582} INFO - 0 downstream tasks scheduled from follow-on schedule check
