[2024-09-12T00:00:00.821+0000] {taskinstance.py:1087} INFO - Dependencies all met for <TaskInstance: covid_data_ingestion_dag.ingest_covid_data scheduled__2024-09-11T00:00:00+00:00 [queued]>
[2024-09-12T00:00:00.826+0000] {taskinstance.py:1087} INFO - Dependencies all met for <TaskInstance: covid_data_ingestion_dag.ingest_covid_data scheduled__2024-09-11T00:00:00+00:00 [queued]>
[2024-09-12T00:00:00.826+0000] {taskinstance.py:1283} INFO - 
--------------------------------------------------------------------------------
[2024-09-12T00:00:00.826+0000] {taskinstance.py:1284} INFO - Starting attempt 1 of 1
[2024-09-12T00:00:00.827+0000] {taskinstance.py:1285} INFO - 
--------------------------------------------------------------------------------
[2024-09-12T00:00:00.834+0000] {taskinstance.py:1304} INFO - Executing <Task(PythonOperator): ingest_covid_data> on 2024-09-11 00:00:00+00:00
[2024-09-12T00:00:00.840+0000] {standard_task_runner.py:55} INFO - Started process 18931 to run task
[2024-09-12T00:00:00.843+0000] {standard_task_runner.py:82} INFO - Running: ['***', 'tasks', 'run', 'covid_data_ingestion_dag', 'ingest_covid_data', 'scheduled__2024-09-11T00:00:00+00:00', '--job-id', '13', '--raw', '--subdir', 'DAGS_FOLDER/data_ingestion.py', '--cfg-path', '/tmp/tmpwru7ejtk']
[2024-09-12T00:00:00.845+0000] {standard_task_runner.py:83} INFO - Job 13: Subtask ingest_covid_data
[2024-09-12T00:00:00.862+0000] {logging_mixin.py:137} WARNING - /home/***/.local/lib/python3.7/site-packages/***/settings.py:249 DeprecationWarning: The sql_alchemy_conn option in [core] has been moved to the sql_alchemy_conn option in [database] - the old setting has been used, but please update your config.
[2024-09-12T00:00:00.884+0000] {logging_mixin.py:137} WARNING - /home/***/.local/lib/python3.7/site-packages/***/utils/sqlalchemy.py:121 DeprecationWarning: The sql_alchemy_conn option in [core] has been moved to the sql_alchemy_conn option in [database] - the old setting has been used, but please update your config.
[2024-09-12T00:00:00.913+0000] {task_command.py:389} INFO - Running <TaskInstance: covid_data_ingestion_dag.ingest_covid_data scheduled__2024-09-11T00:00:00+00:00 [running]> on host 3e9895e193d8
[2024-09-12T00:00:00.976+0000] {taskinstance.py:1513} INFO - Exporting the following env vars:
AIRFLOW_CTX_DAG_OWNER=***
AIRFLOW_CTX_DAG_ID=covid_data_ingestion_dag
AIRFLOW_CTX_TASK_ID=ingest_covid_data
AIRFLOW_CTX_EXECUTION_DATE=2024-09-11T00:00:00+00:00
AIRFLOW_CTX_TRY_NUMBER=1
AIRFLOW_CTX_DAG_RUN_ID=scheduled__2024-09-11T00:00:00+00:00
[2024-09-12T00:00:01.350+0000] {logging_mixin.py:137} WARNING - /home/***/.local/lib/python3.7/site-packages/urllib3/connectionpool.py:1052 InsecureRequestWarning: Unverified HTTPS request is being made to host 'raw.githubusercontent.com'. Adding certificate verification is strongly advised. See: https://urllib3.readthedocs.io/en/1.26.x/advanced-usage.html#ssl-warnings
[2024-09-12T00:00:01.612+0000] {logging_mixin.py:137} INFO - Failed to fetch data: 404 Client Error: Not Found for url: https://raw.githubusercontent.com/CSSEGISandData/COVID-19/master/csse_covid_19_data/csse_covid_19_daily_reports/09-07-2024.csv
[2024-09-12T00:00:01.613+0000] {taskinstance.py:1772} ERROR - Task failed with exception
Traceback (most recent call last):
  File "/home/airflow/.local/lib/python3.7/site-packages/airflow/operators/python.py", line 175, in execute
    return_value = self.execute_callable()
  File "/home/airflow/.local/lib/python3.7/site-packages/airflow/operators/python.py", line 192, in execute_callable
    return self.python_callable(*self.op_args, **self.op_kwargs)
  File "/opt/airflow/dags/data_ingestion.py", line 15, in ingest_covid_data
    response.raise_for_status()  # Raise an exception for HTTP errors
  File "/home/airflow/.local/lib/python3.7/site-packages/requests/models.py", line 1021, in raise_for_status
    raise HTTPError(http_error_msg, response=self)
requests.exceptions.HTTPError: 404 Client Error: Not Found for url: https://raw.githubusercontent.com/CSSEGISandData/COVID-19/master/csse_covid_19_data/csse_covid_19_daily_reports/09-07-2024.csv
[2024-09-12T00:00:01.633+0000] {taskinstance.py:1327} INFO - Marking task as FAILED. dag_id=covid_data_ingestion_dag, task_id=ingest_covid_data, execution_date=20240911T000000, start_date=20240912T000000, end_date=20240912T000001
[2024-09-12T00:00:01.650+0000] {standard_task_runner.py:105} ERROR - Failed to execute job 13 for task ingest_covid_data (404 Client Error: Not Found for url: https://raw.githubusercontent.com/CSSEGISandData/COVID-19/master/csse_covid_19_data/csse_covid_19_daily_reports/09-07-2024.csv; 18931)
[2024-09-12T00:00:01.667+0000] {local_task_job.py:159} INFO - Task exited with return code 1
[2024-09-12T00:00:01.684+0000] {taskinstance.py:2582} INFO - 0 downstream tasks scheduled from follow-on schedule check
